Watching for file changes with StatReloader
C:\Users\daran\PycharmProjects\NewMedCity\MedCare\admin.py changed, reloading.
Watching for file changes with StatReloader
C:\Users\daran\PycharmProjects\NewMedCity\MedCare\admin.py changed, reloading.
Watching for file changes with StatReloader
Internal Server Error: /
Traceback (most recent call last):
  File "C:\Users\daran\PycharmProjects\NewMedCity\.venv\lib\site-packages\django\core\handlers\exception.py", line 55, in inner
    response = get_response(request)
  File "C:\Users\daran\PycharmProjects\NewMedCity\MedCare\LogsUsers.py", line 13, in __call__
    UserActionLog.objects.create(
  File "C:\Users\daran\PycharmProjects\NewMedCity\.venv\lib\site-packages\django\db\models\manager.py", line 87, in manager_method
    return getattr(self.get_queryset(), name)(*args, **kwargs)
  File "C:\Users\daran\PycharmProjects\NewMedCity\.venv\lib\site-packages\django\db\models\query.py", line 656, in create
    obj = self.model(**kwargs)
  File "C:\Users\daran\PycharmProjects\NewMedCity\.venv\lib\site-packages\django\db\models\base.py", line 543, in __init__
    _setattr(self, field.name, rel_obj)
  File "C:\Users\daran\PycharmProjects\NewMedCity\.venv\lib\site-packages\django\db\models\fields\related_descriptors.py", line 266, in __set__
    raise ValueError(
ValueError: Cannot assign "<SimpleLazyObject: <User: daran>>": "UserActionLog.user" must be a "User" instance.
"GET / HTTP/1.1" 500 81577
Internal Server Error: /admin/
Traceback (most recent call last):
  File "C:\Users\daran\PycharmProjects\NewMedCity\.venv\lib\site-packages\django\core\handlers\exception.py", line 55, in inner
    response = get_response(request)
  File "C:\Users\daran\PycharmProjects\NewMedCity\MedCare\LogsUsers.py", line 13, in __call__
    UserActionLog.objects.create(
  File "C:\Users\daran\PycharmProjects\NewMedCity\.venv\lib\site-packages\django\db\models\manager.py", line 87, in manager_method
    return getattr(self.get_queryset(), name)(*args, **kwargs)
  File "C:\Users\daran\PycharmProjects\NewMedCity\.venv\lib\site-packages\django\db\models\query.py", line 656, in create
    obj = self.model(**kwargs)
  File "C:\Users\daran\PycharmProjects\NewMedCity\.venv\lib\site-packages\django\db\models\base.py", line 543, in __init__
    _setattr(self, field.name, rel_obj)
  File "C:\Users\daran\PycharmProjects\NewMedCity\.venv\lib\site-packages\django\db\models\fields\related_descriptors.py", line 266, in __set__
    raise ValueError(
ValueError: Cannot assign "<SimpleLazyObject: <User: daran>>": "UserActionLog.user" must be a "User" instance.
"GET /admin/ HTTP/1.1" 500 81870
C:\Users\daran\PycharmProjects\NewMedCity\MedCare\LogsUsers.py changed, reloading.
Watching for file changes with StatReloader
Internal Server Error: /admin/
Traceback (most recent call last):
  File "C:\Users\daran\PycharmProjects\NewMedCity\.venv\lib\site-packages\django\core\handlers\exception.py", line 55, in inner
    response = get_response(request)
  File "C:\Users\daran\PycharmProjects\NewMedCity\MedCare\LogsUsers.py", line 14, in __call__
    UserActionLog.objects.create(
  File "C:\Users\daran\PycharmProjects\NewMedCity\.venv\lib\site-packages\django\db\models\manager.py", line 87, in manager_method
    return getattr(self.get_queryset(), name)(*args, **kwargs)
  File "C:\Users\daran\PycharmProjects\NewMedCity\.venv\lib\site-packages\django\db\models\query.py", line 656, in create
    obj = self.model(**kwargs)
  File "C:\Users\daran\PycharmProjects\NewMedCity\.venv\lib\site-packages\django\db\models\base.py", line 543, in __init__
    _setattr(self, field.name, rel_obj)
  File "C:\Users\daran\PycharmProjects\NewMedCity\.venv\lib\site-packages\django\db\models\fields\related_descriptors.py", line 266, in __set__
    raise ValueError(
ValueError: Cannot assign "<User: daran>": "UserActionLog.user" must be a "User" instance.
"GET /admin/ HTTP/1.1" 500 82082
Watching for file changes with StatReloader
Internal Server Error: /admin/
Traceback (most recent call last):
  File "C:\Users\daran\PycharmProjects\NewMedCity\.venv\lib\site-packages\django\core\handlers\exception.py", line 55, in inner
    response = get_response(request)
  File "C:\Users\daran\PycharmProjects\NewMedCity\MedCare\LogsUsers.py", line 14, in __call__
    UserActionLog.objects.create(
  File "C:\Users\daran\PycharmProjects\NewMedCity\.venv\lib\site-packages\django\db\models\manager.py", line 87, in manager_method
    return getattr(self.get_queryset(), name)(*args, **kwargs)
  File "C:\Users\daran\PycharmProjects\NewMedCity\.venv\lib\site-packages\django\db\models\query.py", line 656, in create
    obj = self.model(**kwargs)
  File "C:\Users\daran\PycharmProjects\NewMedCity\.venv\lib\site-packages\django\db\models\base.py", line 543, in __init__
    _setattr(self, field.name, rel_obj)
  File "C:\Users\daran\PycharmProjects\NewMedCity\.venv\lib\site-packages\django\db\models\fields\related_descriptors.py", line 266, in __set__
    raise ValueError(
ValueError: Cannot assign "<User: daran>": "UserActionLog.user" must be a "User" instance.
"GET /admin/ HTTP/1.1" 500 82082
C:\Users\daran\PycharmProjects\NewMedCity\MedCare\models.py changed, reloading.
Watching for file changes with StatReloader
Watching for file changes with StatReloader
Internal Server Error: /admin/
Traceback (most recent call last):
  File "C:\Users\daran\PycharmProjects\NewMedCity\.venv\lib\site-packages\django\core\handlers\exception.py", line 55, in inner
    response = get_response(request)
  File "C:\Users\daran\PycharmProjects\NewMedCity\MedCare\LogsUsers.py", line 14, in __call__
    UserActionLog.objects.create(
  File "C:\Users\daran\PycharmProjects\NewMedCity\.venv\lib\site-packages\django\db\models\manager.py", line 87, in manager_method
    return getattr(self.get_queryset(), name)(*args, **kwargs)
  File "C:\Users\daran\PycharmProjects\NewMedCity\.venv\lib\site-packages\django\db\models\query.py", line 656, in create
    obj = self.model(**kwargs)
  File "C:\Users\daran\PycharmProjects\NewMedCity\.venv\lib\site-packages\django\db\models\base.py", line 543, in __init__
    _setattr(self, field.name, rel_obj)
  File "C:\Users\daran\PycharmProjects\NewMedCity\.venv\lib\site-packages\django\db\models\fields\related_descriptors.py", line 266, in __set__
    raise ValueError(
ValueError: Cannot assign "<User: daran>": "UserActionLog.user" must be a "User" instance.
"GET /admin/ HTTP/1.1" 500 82024
Watching for file changes with StatReloader
Internal Server Error: /admin/
Traceback (most recent call last):
  File "C:\Users\daran\PycharmProjects\NewMedCity\.venv\lib\site-packages\django\core\handlers\exception.py", line 55, in inner
    response = get_response(request)
  File "C:\Users\daran\PycharmProjects\NewMedCity\MedCare\LogsUsers.py", line 14, in __call__
    UserActionLog.objects.create(
  File "C:\Users\daran\PycharmProjects\NewMedCity\.venv\lib\site-packages\django\db\models\manager.py", line 87, in manager_method
    return getattr(self.get_queryset(), name)(*args, **kwargs)
  File "C:\Users\daran\PycharmProjects\NewMedCity\.venv\lib\site-packages\django\db\models\query.py", line 656, in create
    obj = self.model(**kwargs)
  File "C:\Users\daran\PycharmProjects\NewMedCity\.venv\lib\site-packages\django\db\models\base.py", line 543, in __init__
    _setattr(self, field.name, rel_obj)
  File "C:\Users\daran\PycharmProjects\NewMedCity\.venv\lib\site-packages\django\db\models\fields\related_descriptors.py", line 266, in __set__
    raise ValueError(
ValueError: Cannot assign "<User: daran>": "UserActionLog.user" must be a "User" instance.
"GET /admin/ HTTP/1.1" 500 82024
Not Found: /favicon.ico
"GET /favicon.ico HTTP/1.1" 404 10116
Internal Server Error: /admin
Traceback (most recent call last):
  File "C:\Users\daran\PycharmProjects\NewMedCity\.venv\lib\site-packages\django\core\handlers\exception.py", line 55, in inner
    response = get_response(request)
  File "C:\Users\daran\PycharmProjects\NewMedCity\MedCare\LogsUsers.py", line 14, in __call__
    UserActionLog.objects.create(
  File "C:\Users\daran\PycharmProjects\NewMedCity\.venv\lib\site-packages\django\db\models\manager.py", line 87, in manager_method
    return getattr(self.get_queryset(), name)(*args, **kwargs)
  File "C:\Users\daran\PycharmProjects\NewMedCity\.venv\lib\site-packages\django\db\models\query.py", line 656, in create
    obj = self.model(**kwargs)
  File "C:\Users\daran\PycharmProjects\NewMedCity\.venv\lib\site-packages\django\db\models\base.py", line 543, in __init__
    _setattr(self, field.name, rel_obj)
  File "C:\Users\daran\PycharmProjects\NewMedCity\.venv\lib\site-packages\django\db\models\fields\related_descriptors.py", line 266, in __set__
    raise ValueError(
ValueError: Cannot assign "<User: daran>": "UserActionLog.user" must be a "User" instance.
"GET /admin HTTP/1.1" 500 81928
Internal Server Error: /login/
Traceback (most recent call last):
  File "C:\Users\daran\PycharmProjects\NewMedCity\.venv\lib\site-packages\django\core\handlers\exception.py", line 55, in inner
    response = get_response(request)
  File "C:\Users\daran\PycharmProjects\NewMedCity\MedCare\LogsUsers.py", line 14, in __call__
    UserActionLog.objects.create(
  File "C:\Users\daran\PycharmProjects\NewMedCity\.venv\lib\site-packages\django\db\models\manager.py", line 87, in manager_method
    return getattr(self.get_queryset(), name)(*args, **kwargs)
  File "C:\Users\daran\PycharmProjects\NewMedCity\.venv\lib\site-packages\django\db\models\query.py", line 656, in create
    obj = self.model(**kwargs)
  File "C:\Users\daran\PycharmProjects\NewMedCity\.venv\lib\site-packages\django\db\models\base.py", line 543, in __init__
    _setattr(self, field.name, rel_obj)
  File "C:\Users\daran\PycharmProjects\NewMedCity\.venv\lib\site-packages\django\db\models\fields\related_descriptors.py", line 266, in __set__
    raise ValueError(
ValueError: Cannot assign "<User: daran>": "UserActionLog.user" must be a "User" instance.
"GET /login/ HTTP/1.1" 500 82148
Internal Server Error: /login/
Traceback (most recent call last):
  File "C:\Users\daran\PycharmProjects\NewMedCity\.venv\lib\site-packages\django\core\handlers\exception.py", line 55, in inner
    response = get_response(request)
  File "C:\Users\daran\PycharmProjects\NewMedCity\MedCare\LogsUsers.py", line 14, in __call__
    UserActionLog.objects.create(
  File "C:\Users\daran\PycharmProjects\NewMedCity\.venv\lib\site-packages\django\db\models\manager.py", line 87, in manager_method
    return getattr(self.get_queryset(), name)(*args, **kwargs)
  File "C:\Users\daran\PycharmProjects\NewMedCity\.venv\lib\site-packages\django\db\models\query.py", line 656, in create
    obj = self.model(**kwargs)
  File "C:\Users\daran\PycharmProjects\NewMedCity\.venv\lib\site-packages\django\db\models\base.py", line 543, in __init__
    _setattr(self, field.name, rel_obj)
  File "C:\Users\daran\PycharmProjects\NewMedCity\.venv\lib\site-packages\django\db\models\fields\related_descriptors.py", line 266, in __set__
    raise ValueError(
ValueError: Cannot assign "<User: daran>": "UserActionLog.user" must be a "User" instance.
"GET /login/ HTTP/1.1" 500 81874
Internal Server Error: /patient/
Traceback (most recent call last):
  File "C:\Users\daran\PycharmProjects\NewMedCity\.venv\lib\site-packages\django\core\handlers\exception.py", line 55, in inner
    response = get_response(request)
  File "C:\Users\daran\PycharmProjects\NewMedCity\MedCare\LogsUsers.py", line 14, in __call__
    UserActionLog.objects.create(
  File "C:\Users\daran\PycharmProjects\NewMedCity\.venv\lib\site-packages\django\db\models\manager.py", line 87, in manager_method
    return getattr(self.get_queryset(), name)(*args, **kwargs)
  File "C:\Users\daran\PycharmProjects\NewMedCity\.venv\lib\site-packages\django\db\models\query.py", line 656, in create
    obj = self.model(**kwargs)
  File "C:\Users\daran\PycharmProjects\NewMedCity\.venv\lib\site-packages\django\db\models\base.py", line 543, in __init__
    _setattr(self, field.name, rel_obj)
  File "C:\Users\daran\PycharmProjects\NewMedCity\.venv\lib\site-packages\django\db\models\fields\related_descriptors.py", line 266, in __set__
    raise ValueError(
ValueError: Cannot assign "<User: daran>": "UserActionLog.user" must be a "User" instance.
"GET /patient/ HTTP/1.1" 500 81808
C:\Users\daran\PycharmProjects\NewMedCity\NewMedCity\settings.py changed, reloading.
